<?xml version="1.0" encoding="UTF-8"?>
<testng-results total="3" passed="2" failed="1" skipped="0">
  <reporter-output>
  </reporter-output>
  <suite started-at="2022-09-29T15:13:01Z" name="Suite" finished-at="2022-09-29T15:13:08Z" duration-ms="6427">
    <groups>
    </groups>
    <test started-at="2022-09-29T15:13:01Z" name="Test" finished-at="2022-09-29T15:13:08Z" duration-ms="6427">
      <class name="JenkinsTest.Test1">
        <test-method signature="t2()[pri:0, instance:JenkinsTest.Test1@7e6ef134]" started-at="2022-09-29T18:13:06Z" name="t2" finished-at="2022-09-29T18:13:08Z" duration-ms="1650" status="PASS">
          <reporter-output>
          </reporter-output>
        </test-method> <!-- t2 -->
      </class> <!-- JenkinsTest.Test1 -->
      <class name="JenkinsTest.Test3">
        <test-method signature="t3()[pri:0, instance:JenkinsTest.Test3@3a4621bd]" started-at="2022-09-29T18:13:01Z" name="t3" finished-at="2022-09-29T18:13:04Z" duration-ms="3117" status="PASS">
          <reporter-output>
          </reporter-output>
        </test-method> <!-- t3 -->
      </class> <!-- JenkinsTest.Test3 -->
      <class name="JenkinsTest.Test2">
        <test-method signature="t3()[pri:0, instance:JenkinsTest.Test2@19b93fa8]" started-at="2022-09-29T18:13:04Z" name="t3" finished-at="2022-09-29T18:13:06Z" duration-ms="1647" status="FAIL">
          <exception class="java.lang.AssertionError">
            <message>
              <![CDATA[expected [1] but found [2]]]>
            </message>
            <full-stacktrace>
              <![CDATA[java.lang.AssertionError: expected [1] but found [2]
	at org.testng.Assert.fail(Assert.java:94)
	at org.testng.Assert.failNotEquals(Assert.java:513)
	at org.testng.Assert.assertEqualsImpl(Assert.java:135)
	at org.testng.Assert.assertEquals(Assert.java:116)
	at org.testng.Assert.assertEquals(Assert.java:389)
	at org.testng.Assert.assertEquals(Assert.java:399)
	at JenkinsTest.Test2.t3(Test2.java:30)
	at java.base/jdk.internal.reflect.NativeMethodAccessorImpl.invoke0(Native Method)
	at java.base/jdk.internal.reflect.NativeMethodAccessorImpl.invoke(NativeMethodAccessorImpl.java:77)
	at java.base/jdk.internal.reflect.DelegatingMethodAccessorImpl.invoke(DelegatingMethodAccessorImpl.java:43)
	at java.base/java.lang.reflect.Method.invoke(Method.java:568)
	at org.testng.internal.MethodInvocationHelper.invokeMethod(MethodInvocationHelper.java:86)
	at org.testng.internal.Invoker.invokeMethod(Invoker.java:643)
	at org.testng.internal.Invoker.invokeTestMethod(Invoker.java:820)
	at org.testng.internal.Invoker.invokeTestMethods(Invoker.java:1128)
	at org.testng.internal.TestMethodWorker.invokeTestMethods(TestMethodWorker.java:129)
	at org.testng.internal.TestMethodWorker.run(TestMethodWorker.java:112)
	at org.testng.TestRunner.privateRun(TestRunner.java:782)
	at org.testng.TestRunner.run(TestRunner.java:632)
	at org.testng.SuiteRunner.runTest(SuiteRunner.java:366)
	at org.testng.SuiteRunner.runSequentially(SuiteRunner.java:361)
	at org.testng.SuiteRunner.privateRun(SuiteRunner.java:319)
	at org.testng.SuiteRunner.run(SuiteRunner.java:268)
	at org.testng.SuiteRunnerWorker.runSuite(SuiteRunnerWorker.java:52)
	at org.testng.SuiteRunnerWorker.run(SuiteRunnerWorker.java:86)
	at org.testng.TestNG.runSuitesSequentially(TestNG.java:1244)
	at org.testng.TestNG.runSuitesLocally(TestNG.java:1169)
	at org.testng.TestNG.run(TestNG.java:1064)
	at org.testng.remote.AbstractRemoteTestNG.run(AbstractRemoteTestNG.java:115)
	at org.testng.remote.RemoteTestNG.initAndRun(RemoteTestNG.java:251)
	at org.testng.remote.RemoteTestNG.main(RemoteTestNG.java:77)
]]>
            </full-stacktrace>
          </exception> <!-- java.lang.AssertionError -->
          <reporter-output>
          </reporter-output>
        </test-method> <!-- t3 -->
      </class> <!-- JenkinsTest.Test2 -->
    </test> <!-- Test -->
  </suite> <!-- Suite -->
</testng-results>
